<?xml version="1.0"?>
<!-- This URDF was automatically created by SolidWorks to URDF Exporter! Originally created by Stephen Brawner (brawner@gmail.com) 
     Commit Version: 1.6.0-4-g7f85cfe  Build Version: 1.6.7995.38578
     For more information, please see http://wiki.ros.org/sw_urdf_exporter -->
<robot xmlns:xacro="http://www.ros.org/wiki/xacro" name="testarm">
   <!-- Constants for robot dimensions -->
  <xacro:property name="PI" value="3.1415926535897931"/>
  <!-- Import all Gazebo-customization elements, including Gazebo colors -->
  <xacro:include filename="$(find model_arm)/urdf/testarm_urdf.gazebo" />
  <!-- Import Rviz colors -->
  <xacro:include filename="$(find model_arm)/urdf/materials.xacro" />

  <link
    name="base_link">
    <inertial>
      <origin
        xyz="2.7756E-17 1.1102E-16 0.10722"
        rpy="0 0 0" />
      <mass
        value="667.25" />
      <inertia
        ixx="21.308"
        ixy="3.2909E-08"
        ixz="4.9251E-16"
        iyy="21.308"
        iyz="-5.9676E-16"
        izz="36.305" />
    </inertial>
    <visual>
      <origin
        xyz="0 0 0"
        rpy="0 0 0" />
      <geometry>
        <mesh
          filename="package://model_arm/meshes/base_link.STL" />
      </geometry>
      <material
        name="">
        <color
          rgba="0.61961 0.40784 0.2 1" />
      </material>
    </visual>
    <collision>
      <origin
        xyz="0 0 0"
        rpy="0 0 0" />
      <geometry>
        <mesh
          filename="package://model_arm/meshes/base_link.STL" />
      </geometry>
    </collision>
  </link>
  <link
    name="l1">
    <inertial>
      <origin
        xyz="-9.8841E-05 1.3203E-07 0.03302"
        rpy="0 0 0" />
      <mass
        value="103.33" />
      <inertia
        ixx="2.3418"
        ixy="-6.0067E-07"
        ixz="0.00010868"
        iyy="1.8272"
        iyz="-1.2951E-06"
        izz="1.6131" />
    </inertial>
    <visual>
      <origin
        xyz="0 0 0"
        rpy="0 0 0" />
      <geometry>
        <mesh
          filename="package://model_arm/meshes/l1.STL" />
      </geometry>
      <material
        name="">
        <color
          rgba="0.77647 0.75686 0.73725 1" />
      </material>
    </visual>
    <collision>
      <origin
        xyz="0 0 0"
        rpy="0 0 0" />
      <geometry>
        <mesh
          filename="package://model_arm/meshes/l1.STL" />
      </geometry>
    </collision>
  </link>
  <joint
    name="j1"
    type="revolute">
    <origin
      xyz="0.00011944 0 0.34027"
      rpy="0 0 0" />
    <parent
      link="base_link" />
    <child
      link="l1" />
    <axis
      xyz="0 0 1" />
    <limit
      lower="0"
      upper="3.1412"
      effort="300"
      velocity="3" />
  </joint>
  <link
    name="l2">
    <inertial>
      <origin
        xyz="4.3999E-12 0.0014837 0.17703"
        rpy="0 0 0" />
      <mass
        value="141.23" />
      <inertia
        ixx="2.7406"
        ixy="-9.097E-10"
        ixz="-3.9887E-10"
        iyy="2.7555"
        iyz="0.011982"
        izz="1.1047" />
    </inertial>
    <visual>
      <origin
        xyz="0 0 0"
        rpy="0 0 0" />
      <geometry>
        <mesh
          filename="package://model_arm/meshes/l2.STL" />
      </geometry>
      <material
        name="">
        <color
          rgba="0.64706 0.61961 0.58824 1" />
      </material>
    </visual>
    <collision>
      <origin
        xyz="0 0 0"
        rpy="0 0 0" />
      <geometry>
        <mesh
          filename="package://model_arm/meshes/l2.STL" />
      </geometry>
    </collision>
  </link>
  <joint
    name="j2"
    type="revolute">
    <origin
      xyz="-0.00011944 0 0.18012"
      rpy="0 0 0" />
    <parent
      link="l1" />
    <child
      link="l2" />
    <axis
      xyz="0 -1 0" />
    <limit
      lower="-1.57"
      upper="1.57"
      effort="200"
      velocity="3" />
  </joint>
  <link
    name="l3">
    <inertial>
      <origin
        xyz="-0.31293 -7.6425E-06 -0.064681"
        rpy="0 0 0" />
      <mass
        value="339.62" />
      <inertia
        ixx="5.1137"
        ixy="-0.00069979"
        ixz="-8.6937E-16"
        iyy="14.561"
        iyz="8.2796E-17"
        izz="16.141" />
    </inertial>
    <visual>
      <origin
        xyz="0 0 0"
        rpy="0 0 0" />
      <geometry>
        <mesh
          filename="package://model_arm/meshes/l3.STL" />
      </geometry>
      <material
        name="">
        <color
          rgba="0.77647 0.75686 0.73725 1" />
      </material>
    </visual>
    <collision>
      <origin
        xyz="0 0 0"
        rpy="0 0 0" />
      <geometry>
        <mesh
          filename="package://model_arm/meshes/l3.STL" />
      </geometry>
    </collision>
  </link>
  <joint
    name="j3"
    type="revolute">
    <origin
      xyz="0 0 0.39751"
      rpy="0 0 0" />
    <parent
      link="l2" />
    <child
      link="l3" />
    <axis
      xyz="0 -1 0" />
    <limit
      lower="0"
      upper="3.142"
      effort="300"
      velocity="3" />
  </joint>
  
   <gazebo>
    <plugin name="gazebo_ros_control" filename="libgazebo_ros_control.so">
      <robotNamespace>/</robotNamespace>
    </plugin>
  </gazebo>
</robot>
